<?xml version="1.0" encoding="utf-8"?>
<!-- This URDF was automatically created by SolidWorks to URDF Exporter! Originally created by Stephen Brawner (brawner@gmail.com) 
     Commit Version: 1.5.1-0-g916b5db  Build Version: 1.5.7152.31018
     For more information, please see http://wiki.ros.org/sw_urdf_exporter -->
<robot
  name="moveo_urdf">
  <link name="dummy">
    </link>  
  <link
    name="base_link">
    <inertial>
      <origin
        xyz="1.4509254414985E-05 1.4418080479528E-08 0.0371569473494335"
        rpy="0 0 0" />
      <mass
        value="0.637576232475362" />
      <inertia
        ixx="0.0015156408925581"
        ixy="-4.43771629740717E-10"
        ixz="-1.56908018120815E-07"
        iyy="0.00151491092167326"
        iyz="-1.90313578254306E-11"
        izz="0.00262377531863523" />
    </inertial>
    <visual>
      <origin
        xyz="0 0 0"
        rpy="0 0 0" />
      <geometry>
        <mesh
          filename="package://moveo_urdf/meshes/base_link.STL" />
      </geometry>
      <material
        name="">
        <color
          rgba="0.792156862745098 0.819607843137255 0.933333333333333 1" />
      </material>
    </visual>
    <collision>
      <origin
        xyz="0 0 0"
        rpy="0 0 0" />
      <geometry>
        <mesh
          filename="package://moveo_urdf/meshes/base_link.STL" />
      </geometry>
    </collision>
  </link>
  <link
    name="moveo_link1">
    <inertial>
      <origin
        xyz="-3.74205976519937E-05 0.000102933216379553 0.0718858336127738"
        rpy="0 0 0" />
      <mass
        value="4.17940224565423" />
      <inertia
        ixx="0.00801802793240662"
        ixy="-3.77835185661566E-05"
        ixz="4.19968816821556E-07"
        iyy="0.00909860267954784"
        iyz="-7.74645429157712E-07"
        izz="0.00700810158542069" />
    </inertial>
    <visual>
      <origin
        xyz="0 0 0"
        rpy="0 0 0" />
      <geometry>
        <mesh
          filename="package://moveo_urdf/meshes/moveo_link1.STL" />
      </geometry>
      <material
        name="">
        <color
          rgba="0.0274509803921569 0.270588235294118 1 1" />
      </material>
    </visual>
    <collision>
      <origin
        xyz="0 0 0"
        rpy="0 0 0" />
      <geometry>
        <mesh
          filename="package://moveo_urdf/meshes/moveo_link1.STL" />
      </geometry>
    </collision>
  </link>
  <joint name="dummy_joint" type="fixed">
    <parent link="dummy"/>
    <child link="base_link"/>
  </joint>
  <joint
    name="moveo_joint1"
    type="revolute">
    <origin
      xyz="0 0 0.0665"
      rpy="0 0 0" />
    <parent
      link="base_link" />
    <child
      link="moveo_link1" />
    <axis
      xyz="0 0 1" />
    <limit
      lower="-1.745"
      upper="1.745"
      effort="10"
      velocity="100" />
  </joint>
  <link
    name="moveo_link2">
    <inertial>
      <origin
        xyz="-0.00166279620451805 -2.18425277667689E-05 0.0793677952499643"
        rpy="0 0 0" />
      <mass
        value="1.91858407284866" />
      <inertia
        ixx="0.00485419294883298"
        ixy="-5.31108558521755E-06"
        ixz="-9.70493599550699E-06"
        iyy="0.0049749177514778"
        iyz="-4.4088516727815E-07"
        izz="0.00289577028575327" />
    </inertial>
    <visual>
      <origin
        xyz="0 0 0"
        rpy="0 0 0" />
      <geometry>
        <mesh
          filename="package://moveo_urdf/meshes/moveo_link2.STL" />
      </geometry>
      <material
        name="">
        <color
          rgba="0.752941176470588 0.752941176470588 0.752941176470588 1" />
      </material>
    </visual>
    <collision>
      <origin
        xyz="0 0 0"
        rpy="0 0 0" />
      <geometry>
        <mesh
          filename="package://moveo_urdf/meshes/moveo_link2.STL" />
      </geometry>
    </collision>
  </link>
  <joint
    name="moveo_joint2"
    type="revolute">
    <origin
      xyz="0 0 0.165"
      rpy="0 0 0" />
    <parent
      link="moveo_link1" />
    <child
      link="moveo_link2" />
    <axis
      xyz="-0.99939 -0.035015 0" />
    <limit
      lower="-1.745"
      upper="1.745"
      effort="10"
      velocity="100" />
  </joint>
  <link
    name="moveo_link3">
    <inertial>
      <origin
        xyz="-0.000345657884119735 -0.000351225772907637 0.03798245037145"
        rpy="0 0 0" />
      <mass
        value="0.654645252090227" />
      <inertia
        ixx="0.00195776364371681"
        ixy="9.62542311161934E-06"
        ixz="1.87503985050398E-06"
        iyy="0.00168280851784142"
        iyz="7.87228062444571E-06"
        izz="0.000424299975732502" />
    </inertial>
    <visual>
      <origin
        xyz="0 0 0"
        rpy="0 0 0" />
      <geometry>
        <mesh
          filename="package://moveo_urdf/meshes/moveo_link3.STL" />
      </geometry>
      <material
        name="">
        <color
          rgba="1 1 1 1" />
      </material>
    </visual>
    <collision>
      <origin
        xyz="0 0 0"
        rpy="0 0 0" />
      <geometry>
        <mesh
          filename="package://moveo_urdf/meshes/moveo_link3.STL" />
      </geometry>
    </collision>
  </link>
  <joint
    name="moveo_joint3"
    type="revolute">
    <origin
      xyz="0.00099794 7.6228E-05 0.22112"
      rpy="0 0 0" />
    <parent
      link="moveo_link2" />
    <child
      link="moveo_link3" />
    <axis
      xyz="-0.99939 -0.035015 0" />
    <limit
      lower="-1.745"
      upper="1.745"
      effort="10"
      velocity="100" />
  </joint>
  <link
    name="moveo_link4">
    <inertial>
      <origin
        xyz="-0.0117603890721236 -0.000629898434795856 0.0443867347629475"
        rpy="0 0 0" />
      <mass
        value="0.623350768745705" />
      <inertia
        ixx="0.000573072936181799"
        ixy="-3.12035283523634E-06"
        ixz="2.16039870123105E-07"
        iyy="0.000664964901562171"
        iyz="1.18610860507001E-05"
        izz="0.000362320763134576" />
    </inertial>
    <visual>
      <origin
        xyz="0 0 0"
        rpy="0 0 0" />
      <geometry>
        <mesh
          filename="package://moveo_urdf/meshes/moveo_link4.STL" />
      </geometry>
      <material
        name="">
        <color
          rgba="0.294117647058824 0.294117647058824 0.294117647058824 1" />
      </material>
    </visual>
    <collision>
      <origin
        xyz="0 0 0"
        rpy="0 0 0" />
      <geometry>
        <mesh
          filename="package://moveo_urdf/meshes/moveo_link4.STL" />
      </geometry>
    </collision>
  </link>
  <joint
    name="moveo_joint4"
    type="revolute">
    <origin
      xyz="2.9924E-05 -0.00085408 0.128"
      rpy="0 0 0" />
    <parent
      link="moveo_link3" />
    <child
      link="moveo_link4" />
    <axis
      xyz="0.00023378 -0.0066725 0.99998" />
    <limit
      lower="-1.745"
      upper="1.745"
      effort="10"
      velocity="100" />
  </joint>
  <link
    name="moveo_link5">
    <inertial>
      <origin
        xyz="-0.00033112445423962 0.000273259127964443 0.0563163811625437"
        rpy="0 0 0" />
      <mass
        value="0.718210813715952" />
      <inertia
        ixx="0.000250128705889318"
        ixy="2.84417291220817E-06"
        ixz="3.220112623644E-08"
        iyy="0.000212437735735121"
        iyz="-1.80185206631517E-06"
        izz="0.000221580519304415" />
    </inertial>
    <visual>
      <origin
        xyz="0 0 0"
        rpy="0 0 0" />
      <geometry>
        <mesh
          filename="package://moveo_urdf/meshes/moveo_link5.STL" />
      </geometry>
      <material
        name="">
        <color
          rgba="0.294117647058824 0.294117647058824 0.294117647058824 1" />
      </material>
    </visual>
    <collision>
      <origin
        xyz="0 0 0"
        rpy="0 0 0" />
      <geometry>
        <mesh
          filename="package://moveo_urdf/meshes/moveo_link5.STL" />
      </geometry>
    </collision>
  </link>
  <joint
    name="moveo_joint5"
    type="revolute">
    <origin
      xyz="2.2209E-05 -0.00063389 0.094998"
      rpy="0 0 0" />
    <parent
      link="moveo_link4" />
    <child
      link="moveo_link5" />
    <axis
      xyz="-0.99935 -0.035919 0" />
    <limit
      lower="-1.745"
      upper="1.745"
      effort="10"
      velocity="100" />
  </joint>
</robot>
