<?xml version="1.0" encoding="utf-8"?>
<!-- This URDF was automatically created by SolidWorks to URDF Exporter! Originally created by Stephen Brawner (brawner@gmail.com) 
     Commit Version: 1.5.1-0-g916b5db  Build Version: 1.5.7152.31018
     For more information, please see http://wiki.ros.org/sw_urdf_exporter -->
<robot
  name="moveo_urdf">
  <link name="dummy">
    </link>
  <link
    name="base_link">
    <inertial>
      <origin
        xyz="1.4509254414985E-05 1.4418080479528E-08 0.0371569473494335"
        rpy="0 0 0" />
      <mass
        value="0.637576232475362" />
      <inertia
        ixx="0.0015156408925581"
        ixy="-4.43771629632297E-10"
        ixz="-1.56908018120803E-07"
        iyy="0.00151491092167326"
        iyz="-1.90313578098267E-11"
        izz="0.00262377531863523" />
    </inertial>
    <visual>
      <origin
        xyz="0 0 0"
        rpy="0 0 0" />
      <geometry>
        <mesh
          filename="package://moveo_urdf/meshes/base_link.STL" />
      </geometry>
      <material
        name="">
        <color
          rgba="0.792156862745098 0.819607843137255 0.933333333333333 1" />
      </material>
    </visual>
    <collision>
      <origin
        xyz="0 0 0"
        rpy="0 0 0" />
      <geometry>
        <mesh
          filename="package://moveo_urdf/meshes/base_link.STL" />
      </geometry>
    </collision>
  </link>
  <link
    name="moveo_link1">
    <inertial>
      <origin
        xyz="-3.51747191506269E-05 -6.08201613527815E-06 0.0718424629061468"
        rpy="0 0 0" />
      <mass
        value="4.14595797854913" />
      <inertia
        ixx="0.00801457400607528"
        ixy="-3.77571262117537E-05"
        ixz="4.05993862398292E-07"
        iyy="0.0090944450424192"
        iyz="-3.56261534862888E-07"
        izz="0.00700608047306451" />
    </inertial>
    <visual>
      <origin
        xyz="0 0 0"
        rpy="0 0 0" />
      <geometry>
        <mesh
          filename="package://moveo_urdf/meshes/moveo_link1.STL" />
      </geometry>
      <material
        name="">
        <color
          rgba="0.0274509803921569 0.270588235294118 1 1" />
      </material>
    </visual>
    <collision>
      <origin
        xyz="0 0 0"
        rpy="0 0 0" />
      <geometry>
        <mesh
          filename="package://moveo_urdf/meshes/moveo_link1.STL" />
      </geometry>
    </collision>
  </link>
  <joint name="dummy_joint" type="fixed">
    <parent link="dummy"/>
    <child link="base_link"/>
  </joint>
  <joint
    name="moveo_joint1"
    type="revolute">
    <origin
      xyz="0 0 0.0665"
      rpy="0 0 0" />
    <parent
      link="base_link" />
    <child
      link="moveo_link1" />
    <axis
      xyz="0 0 1" />
    <limit
      lower="-1.7543"
      upper="1.7543"
      effort="10"
      velocity="100" />
  </joint>
  <link
    name="moveo_link2">
    <inertial>
      <origin
        xyz="-0.00180285808559483 -6.81448021866704E-05 0.079047123508692"
        rpy="0 0 0" />
      <mass
        value="1.90837643765425" />
      <inertia
        ixx="0.00485351088331014"
        ixy="-5.30863649419772E-06"
        ixz="-9.70028580613017E-06"
        iyy="0.00497422940470691"
        iyz="-5.4443357838036E-07"
        izz="0.00289483657354468" />
    </inertial>
    <visual>
      <origin
        xyz="0 0 0"
        rpy="0 0 0" />
      <geometry>
        <mesh
          filename="package://moveo_urdf/meshes/moveo_link2.STL" />
      </geometry>
      <material
        name="">
        <color
          rgba="0.752941176470588 0.752941176470588 0.752941176470588 1" />
      </material>
    </visual>
    <collision>
      <origin
        xyz="0 0 0"
        rpy="0 0 0" />
      <geometry>
        <mesh
          filename="package://moveo_urdf/meshes/moveo_link2.STL" />
      </geometry>
    </collision>
  </link>
  <joint
    name="moveo_joint2"
    type="revolute">
    <origin
      xyz="0 0 0.165"
      rpy="0 0 0" />
    <parent
      link="moveo_link1" />
    <child
      link="moveo_link2" />
    <axis
      xyz="-0.99939 -0.035015 0" />
    <limit
      lower="-1.7543"
      upper="1.7543"
      effort="10"
      velocity="100" />
  </joint>
  <link
    name="moveo_link3">
    <inertial>
      <origin
        xyz="-0.000345657884118611 -0.000351225772940972 0.03798245037145"
        rpy="0 0 0" />
      <mass
        value="0.654645252090226" />
      <inertia
        ixx="0.00195776364371681"
        ixy="9.62542311161929E-06"
        ixz="1.87503985050403E-06"
        iyy="0.00168280851784142"
        iyz="7.87228062444537E-06"
        izz="0.000424299975732501" />
    </inertial>
    <visual>
      <origin
        xyz="0 0 0"
        rpy="0 0 0" />
      <geometry>
        <mesh
          filename="package://moveo_urdf/meshes/moveo_link3.STL" />
      </geometry>
      <material
        name="">
        <color
          rgba="1 1 1 1" />
      </material>
    </visual>
    <collision>
      <origin
        xyz="0 0 0"
        rpy="0 0 0" />
      <geometry>
        <mesh
          filename="package://moveo_urdf/meshes/moveo_link3.STL" />
      </geometry>
    </collision>
  </link>
  <joint
    name="moveo_joint3"
    type="revolute">
    <origin
      xyz="0.00099794 7.6228E-05 0.22112"
      rpy="0 0 0" />
    <parent
      link="moveo_link2" />
    <child
      link="moveo_link3" />
    <axis
      xyz="-0.99939 -0.035015 0" />
    <limit
      lower="-1.7543"
      upper="1.7543"
      effort="10"
      velocity="100" />
  </joint>
  <link
    name="moveo_link4">
    <inertial>
      <origin
        xyz="-0.0118430367007101 -0.000585429400433601 0.0443325578158089"
        rpy="0 0 0" />
      <mass
        value="0.620570358159444" />
      <inertia
        ixx="0.000573052486975875"
        ixy="-3.1183249308072E-06"
        ixz="2.16039061940417E-07"
        iyy="0.000664888103507256"
        iyz="1.18611188577861E-05"
        izz="0.000362238977580599" />
    </inertial>
    <visual>
      <origin
        xyz="0 0 0"
        rpy="0 0 0" />
      <geometry>
        <mesh
          filename="package://moveo_urdf/meshes/moveo_link4.STL" />
      </geometry>
      <material
        name="">
        <color
          rgba="0.294117647058824 0.294117647058824 0.294117647058824 1" />
      </material>
    </visual>
    <collision>
      <origin
        xyz="0 0 0"
        rpy="0 0 0" />
      <geometry>
        <mesh
          filename="package://moveo_urdf/meshes/moveo_link4.STL" />
      </geometry>
    </collision>
  </link>
  <joint
    name="moveo_joint4"
    type="revolute">
    <origin
      xyz="2.9924E-05 -0.00085408 0.128"
      rpy="0 0 0" />
    <parent
      link="moveo_link3" />
    <child
      link="moveo_link4" />
    <axis
      xyz="0.00023378 -0.0066725 0.99998" />
    <limit
      lower="-1.7543"
      upper="1.7543"
      effort="10"
      velocity="100" />
  </joint>
  <link
    name="moveo_link5">
    <inertial>
      <origin
        xyz="0.00191346671544323 6.97761103512218E-05 0.0204394908609966"
        rpy="0 0 0" />
      <mass
        value="0.21298004137125" />
      <inertia
        ixx="0.00011767621055808"
        ixy="9.27373246707416E-07"
        ixz="8.7284451821713E-07"
        iyy="8.9306428046248E-05"
        iyz="4.12857172995059E-08"
        izz="6.54924339245632E-05" />
    </inertial>
    <visual>
      <origin
        xyz="0 0 0"
        rpy="0 0 0" />
      <geometry>
        <mesh
          filename="package://moveo_urdf/meshes/moveo_link5.STL" />
      </geometry>
      <material
        name="">
        <color
          rgba="0.294117647058824 0.294117647058824 0.294117647058824 1" />
      </material>
    </visual>
    <collision>
      <origin
        xyz="0 0 0"
        rpy="0 0 0" />
      <geometry>
        <mesh
          filename="package://moveo_urdf/meshes/moveo_link5.STL" />
      </geometry>
    </collision>
  </link>
  <joint
    name="moveo_joint5"
    type="revolute">
    <origin
      xyz="2.2209E-05 -0.00063389 0.094998"
      rpy="0 0 0" />
    <parent
      link="moveo_link4" />
    <child
      link="moveo_link5" />
    <axis
      xyz="-0.99935 -0.035919 0" />
    <limit
      lower="-1.7543"
      upper="1.7543"
      effort="10"
      velocity="100" />
  </joint>
  <link
    name="end_effector_link">
    <inertial>
      <origin
        xyz="-0.00628469425390386 -9.29486326957663E-05 -0.035952905600982"
        rpy="0 0 0" />
      <mass
        value="0.0102853681251992" />
      <inertia
        ixx="3.99650975192331E-06"
        ixy="4.76464958839803E-09"
        ixz="-6.0202731381197E-07"
        iyy="3.92703906685667E-06"
        iyz="-8.96235307277054E-09"
        izz="5.52843713020629E-07" />
    </inertial>
    <visual>
      <origin
        xyz="0 0 0"
        rpy="0 0 0" />
      <geometry>
        <mesh
          filename="package://moveo_urdf/meshes/end_effector_link.STL" />
      </geometry>
      <material
        name="">
        <color
          rgba="0.6 1 0.27843137254902 1" />
      </material>
    </visual>
    <collision>
      <origin
        xyz="0 0 0"
        rpy="0 0 0" />
      <geometry>
        <mesh
          filename="package://moveo_urdf/meshes/end_effector_link.STL" />
      </geometry>
    </collision>
  </link>
  <joint
    name="end_effector_joint"
    type="fixed">
    <origin
      xyz="-0.040668 -0.001931 0.12926"
      rpy="0 0 0" />
    <parent
      link="moveo_link5" />
    <child
      link="end_effector_link" />
    <axis
      xyz="0 0 0" />
  </joint>
</robot>
