<?xml version="1.0" encoding="utf-8"?>
<!-- This URDF was automatically created by SolidWorks to URDF Exporter! Originally created by Stephen Brawner (brawner@gmail.com) 
     Commit Version: 1.5.1-0-g916b5db  Build Version: 1.5.7152.31018
     For more information, please see http://wiki.ros.org/sw_urdf_exporter -->
<robot
  name="moveo_urdf">
  <link
    name="dummy">
  </link>
  <link
    name="base_link">
    <inertial>
      <origin
        xyz="-3.22852857884137E-06 0.000468992473105445 0.0707023084968957"
        rpy="0 0 0" />
      <mass
        value="2.57069193907154" />
      <inertia
        ixx="0.0121028244575046"
        ixy="3.85118155811449E-06"
        ixz="5.13088561046958E-07"
        iyy="0.0124093178776122"
        iyz="-7.44356007695055E-05"
        izz="0.0189004175391313" />
    </inertial>
    <visual>
      <origin
        xyz="0 0 0"
        rpy="0 0 0" />
      <geometry>
        <mesh
          filename="package://moveo_urdf/meshes/base_link.STL" />
      </geometry>
      <material
        name="">
        <color
          rgba="0.294117647058824 0.294117647058824 0.294117647058824 1" />
      </material>
    </visual>
    <collision>
      <origin
        xyz="0 0 0"
        rpy="0 0 0" />
      <geometry>
        <mesh
          filename="package://moveo_urdf/meshes/base_link.STL" />
      </geometry>
    </collision>
  </link>
  <link
    name="moveo_link1">
    <inertial>
      <origin
        xyz="0.000291566177196514 0.000104681575191917 0.072805715614663"
        rpy="0 0 0" />
      <mass
        value="4.15952822957478" />
      <inertia
        ixx="0.00800157509690919"
        ixy="2.13127851665445E-07"
        ixz="3.261928372623E-07"
        iyy="0.00908128774866342"
        iyz="-7.85160687707341E-07"
        izz="0.00697011263828059" />
    </inertial>
    <visual>
      <origin
        xyz="0 0 0"
        rpy="0 0 0" />
      <geometry>
        <mesh
          filename="package://moveo_urdf/meshes/moveo_link1.STL" />
      </geometry>
      <material
        name="">
        <color
          rgba="0.0274509803921569 0.270588235294118 1 1" />
      </material>
    </visual>
    <collision>
      <origin
        xyz="0 0 0"
        rpy="0 0 0" />
      <geometry>
        <mesh
          filename="package://moveo_urdf/meshes/moveo_link1.STL" />
      </geometry>
    </collision>
  </link>
  <joint name="dummy_joint" type="fixed">
    <parent link="dummy"/>
    <child link="base_link"/>
  </joint>
  <joint
    name="moveo_joint1"
    type="continuous">
    <origin
      xyz="0 0 0.1715"
      rpy="0 0 0" />
    <parent
      link="base_link" />
    <child
      link="moveo_link1" />
    <axis
      xyz="0 0 1" />
    <limit
      lower="-3.14159"
      upper="3.14159"
      effort="10"
      velocity="100" />
  </joint>
  <link
    name="moveo_link2">
    <inertial>
      <origin
        xyz="-0.00119973304767501 6.46250961949257E-05 0.0828696519085527"
        rpy="0 0 0" />
      <mass
        value="1.8480863757448" />
      <inertia
        ixx="0.00467369767077732"
        ixy="-1.13285165584517E-06"
        ixz="-9.21611867880948E-07"
        iyy="0.00481325684203169"
        iyz="5.23927474254575E-07"
        izz="0.00284875642253876" />
    </inertial>
    <visual>
      <origin
        xyz="0 0 0"
        rpy="0 0 0" />
      <geometry>
        <mesh
          filename="package://moveo_urdf/meshes/moveo_link2.STL" />
      </geometry>
      <material
        name="">
        <color
          rgba="0.752941176470588 0.752941176470588 0.752941176470588 1" />
      </material>
    </visual>
    <collision>
      <origin
        xyz="0 0 0"
        rpy="0 0 0" />
      <geometry>
        <mesh
          filename="package://moveo_urdf/meshes/moveo_link2.STL" />
      </geometry>
    </collision>
  </link>
  <joint
    name="moveo_joint2"
    type="revolute">
    <origin
      xyz="0 0 0.165000000000003"
      rpy="0 0 0" />
    <parent
      link="moveo_link1" />
    <child
      link="moveo_link2" />
    <axis
      xyz="-1 0 0" />
    <limit
      lower="-1"
      upper="2.15"
      effort="10"
      velocity="100" />
  </joint>
  <link
    name="moveo_link3">
    <inertial>
      <origin
        xyz="0.000651790401553304 -0.000105937403500594 0.038019057191962"
        rpy="0 0 0" />
      <mass
        value="0.617310670458712" />
      <inertia
        ixx="0.00193840773537008"
        ixy="-9.64839957002823E-08"
        ixz="-3.50045059196063E-07"
        iyy="0.00165549309984829"
        iyz="-2.91720777600348E-07"
        izz="0.000420883756965661" />
    </inertial>
    <visual>
      <origin
        xyz="0 0 0"
        rpy="0 0 0" />
      <geometry>
        <mesh
          filename="package://moveo_urdf/meshes/moveo_link3.STL" />
      </geometry>
      <material
        name="">
        <color
          rgba="1 1 1 1" />
      </material>
    </visual>
    <collision>
      <origin
        xyz="0 0 0"
        rpy="0 0 0" />
      <geometry>
        <mesh
          filename="package://moveo_urdf/meshes/moveo_link3.STL" />
      </geometry>
    </collision>
  </link>
  <joint
    name="moveo_joint3"
    type="revolute">
    <origin
      xyz="0.001 0 0.22112"
      rpy="0 0 0" />
    <parent
      link="moveo_link2" />
    <child
      link="moveo_link3" />
    <axis
      xyz="-1 0 0" />
    <limit
      lower="0"
      upper="2.15"
      effort="10"
      velocity="100" />
  </joint>
  <link
    name="moveo_link4">
    <inertial>
      <origin
        xyz="0.00620778315224925 -2.10975020784043E-05 0.0531193403868246"
        rpy="0 0 0" />
      <mass
        value="0.346469873235592" />
      <inertia
        ixx="0.000291908908482204"
        ixy="2.22357306174176E-07"
        ixz="-6.43854660632878E-07"
        iyy="0.000391793891239351"
        iyz="-1.81852520916988E-09"
        izz="0.00030871484098949" />
    </inertial>
    <visual>
      <origin
        xyz="0 0 0"
        rpy="0 0 0" />
      <geometry>
        <mesh
          filename="package://moveo_urdf/meshes/moveo_link4.STL" />
      </geometry>
      <material
        name="">
        <color
          rgba="0.792156862745098 0.819607843137255 0.933333333333333 1" />
      </material>
    </visual>
    <collision>
      <origin
        xyz="0 0 0"
        rpy="0 0 0" />
      <geometry>
        <mesh
          filename="package://moveo_urdf/meshes/moveo_link4.STL" />
      </geometry>
    </collision>
  </link>
  <joint
    name="moveo_joint4"
    type="revolute">
    <origin
      xyz="0 0 0.1275"
      rpy="0 0 0" />
    <parent
      link="moveo_link3" />
    <child
      link="moveo_link4" />
    <axis
      xyz="0 0 1" />
    <limit
      lower="-1.3745"
      upper="4.5161"
      effort="10"
      velocity="100" />
  </joint>
  <link
    name="moveo_link5">
    <inertial>
      <origin
        xyz="0.000293805193654822 -8.83634265758104E-09 0.00400995804578985"
        rpy="0 0 0" />
      <mass
        value="0.156134490695851" />
      <inertia
        ixx="0.000104684957567226"
        ixy="1.33186431650642E-11"
        ixz="-9.0241907497207E-08"
        iyy="6.64394541009088E-05"
        iyz="-2.56604902339445E-12"
        izz="5.32122469249959E-05" />
    </inertial>
    <visual>
      <origin
        xyz="0 0 0"
        rpy="0 0 0" />
      <geometry>
        <mesh
          filename="package://moveo_urdf/meshes/moveo_link5.STL" />
      </geometry>
      <material
        name="">
        <color
          rgba="0.0980392156862745 0.0980392156862745 0.0980392156862745 1" />
      </material>
    </visual>
    <collision>
      <origin
        xyz="0 0 0"
        rpy="0 0 0" />
      <geometry>
        <mesh
          filename="package://moveo_urdf/meshes/moveo_link5.STL" />
      </geometry>
    </collision>
  </link>
  <joint
    name="moveo_joint5"
    type="revolute">
    <origin
      xyz="0 0.0001353 0.096"
      rpy="0 0 0" />
    <parent
      link="moveo_link4" />
    <child
      link="moveo_link5" />
    <axis
      xyz="1 0 0" />
    <limit
      lower="-1.4677"
      upper="1.9495"
      effort="10"
      velocity="100" />
  </joint>
  <link
    name="moveo_nozzle_link">
    <inertial>
      <origin
        xyz="0.0107686264409295 -0.0325615730330498 0.0706687293479958"
        rpy="0 0 0" />
      <mass
        value="0.571607414522843" />
      <inertia
        ixx="0.000156332259064947"
        ixy="-4.79451137839047E-07"
        ixz="8.18783307336904E-07"
        iyy="0.000175458954406939"
        iyz="8.62317052926561E-06"
        izz="0.000141924473429863" />
    </inertial>
    <visual>
      <origin
        xyz="0 0 0"
        rpy="0 0 0" />
      <geometry>
        <mesh
          filename="package://moveo_urdf/meshes/moveo_nozzle_link.STL" />
      </geometry>
      <material
        name="">
        <color
          rgba="0.427450980392157 0.447058823529412 0.427450980392157 1" />
      </material>
    </visual>
    <collision>
      <origin
        xyz="0 0 0"
        rpy="0 0 0" />
      <geometry>
        <mesh
          filename="package://moveo_urdf/meshes/moveo_nozzle_link.STL" />
      </geometry>
    </collision>
  </link>
  <joint
    name="moveo_nozzle_joint"
    type="fixed">
    <origin
      xyz="-0.0109 -0.0386 0.1513"
      rpy="-3.14159265358979 0 0" />
    <parent
      link="moveo_link5" />
    <child
      link="moveo_nozzle_link" />
    <axis
      xyz="0 0 0" />
  </joint>
</robot>
