<?xml version="1.0" encoding="utf-8"?>
<!-- This URDF was automatically created by SolidWorks to URDF Exporter! Originally created by Stephen Brawner (brawner@gmail.com) 
     Commit Version: 1.5.1-0-g916b5db  Build Version: 1.5.7152.31018
     For more information, please see http://wiki.ros.org/sw_urdf_exporter -->
<robot
  name="moveo_urdf">
  <link
    name="dummy">
  </link>
  <link
    name="base_link">
    <inertial>
      <origin
        xyz="1.4509254414985E-05 1.4418080479528E-08 0.0371569473494335"
        rpy="0 0 0" />
      <mass
        value="0.637576232475362" />
      <inertia
        ixx="0.0015156408925581"
        ixy="-4.43771629794927E-10"
        ixz="-1.56908018120832E-07"
        iyy="0.00151491092167326"
        iyz="-1.90313578126259E-11"
        izz="0.00262377531863523" />
    </inertial>
    <visual>
      <origin
        xyz="0 0 0"
        rpy="0 0 0" />
      <geometry>
        <mesh
          filename="package://moveo_urdf/meshes/base_link.STL" />
      </geometry>
      <material
        name="">
        <color
          rgba="0.792156862745098 0.819607843137255 0.933333333333333 1" />
      </material>
    </visual>
    <collision>
      <origin
        xyz="0 0 0"
        rpy="0 0 0" />
      <geometry>
        <mesh
          filename="package://moveo_urdf/meshes/base_link.STL" />
      </geometry>
    </collision>
  </link>
  <link
    name="moveo_link1">
    <inertial>
      <origin
        xyz="0.000388935695049442 0.000117285399136136 0.0724091366065916"
        rpy="0 0 0" />
      <mass
        value="4.20302329882691" />
      <inertia
        ixx="0.00802935705417133"
        ixy="-3.75894553050721E-05"
        ixz="4.1996881682366E-07"
        iyy="0.00910439971414678"
        iyz="-7.74645429161709E-07"
        izz="0.00701389182071989" />
    </inertial>
    <visual>
      <origin
        xyz="0 0 0"
        rpy="0 0 0" />
      <geometry>
        <mesh
          filename="package://moveo_urdf/meshes/moveo_link1.STL" />
      </geometry>
      <material
        name="">
        <color
          rgba="0.0274509803921569 0.270588235294118 1 1" />
      </material>
    </visual>
    <collision>
      <origin
        xyz="0 0 0"
        rpy="0 0 0" />
      <geometry>
        <mesh
          filename="package://moveo_urdf/meshes/moveo_link1.STL" />
      </geometry>
    </collision>
  </link>
  <joint name="dummy_joint" type="fixed">
    <parent link="dummy"/>
    <child link="base_link"/>
  </joint>
  <joint
    name="moveo_joint1"
    type="revolute">
    <origin
      xyz="0 0 0.0665"
      rpy="0 0 0" />
    <parent
      link="base_link" />
    <child
      link="moveo_link1" />
    <axis
      xyz="0 0 1" />
    <limit
      lower="-1.746"
      upper="1.746"
      effort="10"
      velocity="100" />
  </joint>
  <link
    name="moveo_link2">
    <inertial>
      <origin
        xyz="-0.00166279620270182 -2.18425264842392E-05 0.0793677952480683"
        rpy="0 0 0" />
      <mass
        value="1.91858407295863" />
      <inertia
        ixx="0.00485419294906105"
        ixy="-5.31108560330583E-06"
        ixz="-9.70493602574839E-06"
        iyy="0.00497491775165112"
        iyz="-4.40885265979692E-07"
        izz="0.00289577028581175" />
    </inertial>
    <visual>
      <origin
        xyz="0 0 0"
        rpy="0 0 0" />
      <geometry>
        <mesh
          filename="package://moveo_urdf/meshes/moveo_link2.STL" />
      </geometry>
      <material
        name="">
        <color
          rgba="0.792156862745098 0.819607843137255 0.933333333333333 1" />
      </material>
    </visual>
    <collision>
      <origin
        xyz="0 0 0"
        rpy="0 0 0" />
      <geometry>
        <mesh
          filename="package://moveo_urdf/meshes/moveo_link2.STL" />
      </geometry>
    </collision>
  </link>
  <joint
    name="moveo_joint2"
    type="revolute">
    <origin
      xyz="0 0 0.165"
      rpy="0 0 0" />
    <parent
      link="moveo_link1" />
    <child
      link="moveo_link2" />
    <axis
      xyz="-0.99939 -0.035015 0" />
    <limit
      lower="-1.746"
      upper="1.746"
      effort="10"
      velocity="100" />
  </joint>
  <link
    name="moveo_link3">
    <inertial>
      <origin
        xyz="-0.000345657884120526 -0.000351225772886155 0.0379824503714574"
        rpy="0 0 0" />
      <mass
        value="0.654645252090227" />
      <inertia
        ixx="0.00195776364371681"
        ixy="9.62542311161918E-06"
        ixz="1.87503985050367E-06"
        iyy="0.00168280851784142"
        iyz="7.87228062444538E-06"
        izz="0.000424299975732501" />
    </inertial>
    <visual>
      <origin
        xyz="0 0 0"
        rpy="0 0 0" />
      <geometry>
        <mesh
          filename="package://moveo_urdf/meshes/moveo_link3.STL" />
      </geometry>
      <material
        name="">
        <color
          rgba="1 1 1 1" />
      </material>
    </visual>
    <collision>
      <origin
        xyz="0 0 0"
        rpy="0 0 0" />
      <geometry>
        <mesh
          filename="package://moveo_urdf/meshes/moveo_link3.STL" />
      </geometry>
    </collision>
  </link>
  <joint
    name="moveo_joint3"
    type="revolute">
    <origin
      xyz="0.00099794 7.6228E-05 0.22112"
      rpy="0 0 0" />
    <parent
      link="moveo_link2" />
    <child
      link="moveo_link3" />
    <axis
      xyz="-0.99939 -0.035015 0" />
    <limit
      lower="-1.746"
      upper="1.746"
      effort="10"
      velocity="100" />
  </joint>
  <link
    name="moveo_link4">
    <inertial>
      <origin
        xyz="-0.0117603890721244 -0.000629898434774401 0.044386734762955"
        rpy="0 0 0" />
      <mass
        value="0.623350768745701" />
      <inertia
        ixx="0.000573072936195744"
        ixy="-3.12035282945795E-06"
        ixz="2.16039870125152E-07"
        iyy="0.000664964901564562"
        iyz="1.18610860507002E-05"
        izz="0.000362320763150916" />
    </inertial>
    <visual>
      <origin
        xyz="0 0 0"
        rpy="0 0 0" />
      <geometry>
        <mesh
          filename="package://moveo_urdf/meshes/moveo_link4.STL" />
      </geometry>
      <material
        name="">
        <color
          rgba="0.294117647058824 0.294117647058824 0.294117647058824 1" />
      </material>
    </visual>
    <collision>
      <origin
        xyz="0 0 0"
        rpy="0 0 0" />
      <geometry>
        <mesh
          filename="package://moveo_urdf/meshes/moveo_link4.STL" />
      </geometry>
    </collision>
  </link>
  <joint
    name="moveo_joint4"
    type="revolute">
    <origin
      xyz="2.9924E-05 -0.00085408 0.128"
      rpy="0 0 0" />
    <parent
      link="moveo_link3" />
    <child
      link="moveo_link4" />
    <axis
      xyz="0.00023378 -0.0066725 0.99998" />
    <limit
      lower="-3.1416"
      upper="3.1416"
      effort="10"
      velocity="100" />
  </joint>
  <link
    name="moveo_link5">
    <inertial>
      <origin
        xyz="-0.000382105654023621 -9.41031890042132E-06 0.00379979047812995"
        rpy="0 0 0" />
      <mass
        value="0.157708113613127" />
      <inertia
        ixx="0.000105894843359679"
        ixy="1.3748110016056E-06"
        ixz="1.76753717969543E-07"
        iyy="6.76991840495815E-05"
        iyz="-9.97031846386346E-09"
        izz="5.33063232104759E-05" />
    </inertial>
    <visual>
      <origin
        xyz="0 0 0"
        rpy="0 0 0" />
      <geometry>
        <mesh
          filename="package://moveo_urdf/meshes/moveo_link5.STL" />
      </geometry>
      <material
        name="">
        <color
          rgba="0.0980392156862745 0.0980392156862745 0.0980392156862745 1" />
      </material>
    </visual>
    <collision>
      <origin
        xyz="0 0 0"
        rpy="0 0 0" />
      <geometry>
        <mesh
          filename="package://moveo_urdf/meshes/moveo_link5.STL" />
      </geometry>
    </collision>
  </link>
  <joint
    name="moveo_joint5"
    type="revolute">
    <origin
      xyz="2.2209E-05 -0.00063389 0.094998"
      rpy="0 0 0" />
    <parent
      link="moveo_link4" />
    <child
      link="moveo_link5" />
    <axis
      xyz="-0.99935 -0.035919 0" />
    <limit
      lower="-1.746"
      upper="1.746"
      effort="10"
      velocity="100" />
  </joint>
  <link
    name="moveo_nozzle_link">
    <inertial>
      <origin
        xyz="0.0105974452771288 -0.0315371193389724 0.0439720755439347"
        rpy="0 0 0" />
      <mass
        value="0.562206501752102" />
      <inertia
        ixx="0.000147298604864562"
        ixy="-2.0699137349465E-07"
        ixz="-1.48391188660509E-06"
        iyy="0.000169354181279456"
        iyz="2.07145281538154E-06"
        izz="0.000147780132874431" />
    </inertial>
    <visual>
      <origin
        xyz="0 0 0"
        rpy="0 0 0" />
      <geometry>
        <mesh
          filename="package://moveo_urdf/meshes/moveo_nozzle_link.STL" />
      </geometry>
      <material
        name="">
        <color
          rgba="0.792156862745098 0.819607843137255 0.933333333333333 1" />
      </material>
    </visual>
    <collision>
      <origin
        xyz="0 0 0"
        rpy="0 0 0" />
      <geometry>
        <mesh
          filename="package://moveo_urdf/meshes/moveo_nozzle_link.STL" />
      </geometry>
    </collision>
  </link>
  <joint
    name="moveo_nozzle_joint"
    type="fixed">
    <origin
      xyz="-0.012488 0.043982 0.10635"
      rpy="1.5697 0 0.035926" />
    <parent
      link="moveo_link5" />
    <child
      link="moveo_nozzle_link" />
    <axis
      xyz="0 0 0" />
  </joint>
</robot>