<?xml version="1.0" encoding="utf-8"?>
<!-- This URDF was automatically created by SolidWorks to URDF Exporter! Originally created by Stephen Brawner (brawner@gmail.com) 
     Commit Version: 1.5.1-0-g916b5db  Build Version: 1.5.7152.31018
     For more information, please see http://wiki.ros.org/sw_urdf_exporter -->
<robot
  name="moveo_urdf">
  <link
    name="dummy">
  </link>
  <link
    name="base_link">
    <inertial>
      <origin
        xyz="5.45917075045477E-06 -1.85712902611712E-07 0.0829241965056019"
        rpy="0 0 0" />
      <mass
        value="1.69354568563049" />
      <inertia
        ixx="0.010099500851289"
        ixy="-2.61049841556761E-08"
        ixz="-5.19386175718213E-07"
        iyy="0.0100987728251248"
        iyz="1.79952394590515E-08"
        izz="0.0147123362558938" />
    </inertial>
    <visual>
      <origin
        xyz="0 0 0"
        rpy="0 0 0" />
      <geometry>
        <mesh
          filename="package://moveo_urdf/meshes/base_link.STL" />
      </geometry>
      <material
        name="">
        <color
          rgba="0.792156862745098 0.819607843137255 0.933333333333333 1" />
      </material>
    </visual>
    <collision>
      <origin
        xyz="0 0 0"
        rpy="0 0 0" />
      <geometry>
        <mesh
          filename="package://moveo_urdf/meshes/base_link.STL" />
      </geometry>
    </collision>
  </link>
  <link
    name="moveo_link1">
    <inertial>
      <origin
        xyz="0.000290542466276675 0.000104314029573394 0.0725847755196123"
        rpy="0 0 0" />
      <mass
        value="4.17418410914588" />
      <inertia
        ixx="0.00801009404700573"
        ixy="2.49319002911452E-07"
        ixz="3.49351920539095E-07"
        iyy="0.00908981026842451"
        iyz="-7.85160909518669E-07"
        izz="0.00698678648688924" />
    </inertial>
    <visual>
      <origin
        xyz="0 0 0"
        rpy="0 0 0" />
      <geometry>
        <mesh
          filename="package://moveo_urdf/meshes/moveo_link1.STL" />
      </geometry>
      <material
        name="">
        <color
          rgba="0.0588235294117647 0.647058823529412 1 1" />
      </material>
    </visual>
    <collision>
      <origin
        xyz="0 0 0"
        rpy="0 0 0" />
      <geometry>
        <mesh
          filename="package://moveo_urdf/meshes/moveo_link1.STL" />
      </geometry>
    </collision>
  </link>
  <joint name="dummy_joint" type="fixed">
    <parent link="dummy"/>
    <child link="base_link"/>
  </joint>
  <joint
    name="moveo_joint1"
    type="continuous">
    <origin
      xyz="0 0 0.1515"
      rpy="0 0 0" />
    <parent
      link="base_link" />
    <child
      link="moveo_link1" />
    <axis
      xyz="0 0 1" />
    <limit
      lower="-3.14159"
      upper="3.14159"
      effort="10"
      velocity="100" />
  </joint>
  <link
    name="moveo_link2">
    <inertial>
      <origin
        xyz="-0.000974255519850864 5.97118788164541E-05 0.0814278104555238"
        rpy="0 0 0" />
      <mass
        value="1.88123214398999" />
      <inertia
        ixx="0.00474643325471749"
        ixy="-1.0812899204351E-06"
        ixz="-4.59236741979913E-06"
        iyy="0.00487855386531353"
        iyz="-1.20427580615581E-06"
        izz="0.00286834022016079" />
    </inertial>
    <visual>
      <origin
        xyz="0 0 0"
        rpy="0 0 0" />
      <geometry>
        <mesh
          filename="package://moveo_urdf/meshes/moveo_link2.STL" />
      </geometry>
      <material
        name="">
        <color
          rgba="0.752941176470588 0.752941176470588 0.752941176470588 1" />
      </material>
    </visual>
    <collision>
      <origin
        xyz="0 0 0"
        rpy="0 0 0" />
      <geometry>
        <mesh
          filename="package://moveo_urdf/meshes/moveo_link2.STL" />
      </geometry>
    </collision>
  </link>
  <joint
    name="moveo_joint2"
    type="revolute">
    <origin
      xyz="0 0 0.165"
      rpy="0 0 0" />
    <parent
      link="moveo_link1" />
    <child
      link="moveo_link2" />
    <axis
      xyz="-1 0 0" />
    <limit
      lower="-1"
      upper="2.15"
      effort="10"
      velocity="100" />
  </joint>
  <link
    name="moveo_link3">
    <inertial>
      <origin
        xyz="0.000450469686335109 -0.000360649076419861 0.0380467749910122"
        rpy="0 0 0" />
      <mass
        value="0.612824408729849" />
      <inertia
        ixx="0.00193777426212301"
        ixy="-9.04773992473659E-08"
        ixz="-4.44369457725175E-07"
        iyy="0.00165446015354504"
        iyz="7.94769828190117E-06"
        izz="0.000420397236390847" />
    </inertial>
    <visual>
      <origin
        xyz="0 0 0"
        rpy="0 0 0" />
      <geometry>
        <mesh
          filename="package://moveo_urdf/meshes/moveo_link3.STL" />
      </geometry>
      <material
        name="">
        <color
          rgba="1 1 1 1" />
      </material>
    </visual>
    <collision>
      <origin
        xyz="0 0 0"
        rpy="0 0 0" />
      <geometry>
        <mesh
          filename="package://moveo_urdf/meshes/moveo_link3.STL" />
      </geometry>
    </collision>
  </link>
  <joint
    name="moveo_joint3"
    type="revolute">
    <origin
      xyz="0.001 6.9184E-05 0.22112"
      rpy="0 0 0" />
    <parent
      link="moveo_link2" />
    <child
      link="moveo_link3" />
    <axis
      xyz="-1 0 0" />
    <limit
      lower="0"
      upper="2.15"
      effort="10"
      velocity="100" />
  </joint>
  <link
    name="moveo_link4">
    <inertial>
      <origin
        xyz="-0.00594673737670647 -0.000149724614217361 0.050705557078197"
        rpy="0 0 0" />
      <mass
        value="0.360582345944525" />
      <inertia
        ixx="0.000302010238141853"
        ixy="1.21866295741008E-07"
        ixz="7.32527516280694E-07"
        iyy="0.000405461655997867"
        iyz="5.46126570905353E-07"
        izz="0.000321346704608612" />
    </inertial>
    <visual>
      <origin
        xyz="0 0 0"
        rpy="0 0 0" />
      <geometry>
        <mesh
          filename="package://moveo_urdf/meshes/moveo_link4.STL" />
      </geometry>
      <material
        name="">
        <color
          rgba="0.294117647058824 0.294117647058824 0.294117647058824 1" />
      </material>
    </visual>
    <collision>
      <origin
        xyz="0 0 0"
        rpy="0 0 0" />
      <geometry>
        <mesh
          filename="package://moveo_urdf/meshes/moveo_link4.STL" />
      </geometry>
    </collision>
  </link>
  <joint
    name="moveo_joint4"
    type="revolute">
    <origin
      xyz="0 -0.0008546 0.128"
      rpy="0 0 0" />
    <parent
      link="moveo_link3" />
    <child
      link="moveo_link4" />
    <axis
      xyz="0 -0.0066766 0.99998" />
    <limit
      lower="-0.08726"
      upper="0.08726"
      effort="10"
      velocity="100" />
  </joint>
  <link
    name="moveo_link5">
    <inertial>
      <origin
        xyz="-0.000293811858598683 -1.95625681808365E-05 0.00400990984102956"
        rpy="0 0 0" />
      <mass
        value="0.156134491837058" />
      <inertia
        ixx="0.000104684926346323"
        ixy="3.41613964226514E-08"
        ixz="9.04940008580869E-08"
        iyy="6.64391787775182E-05"
        iyz="6.37654518767953E-08"
        izz="5.32125548176092E-05" />
    </inertial>
    <visual>
      <origin
        xyz="0 0 0"
        rpy="0 0 0" />
      <geometry>
        <mesh
          filename="package://moveo_urdf/meshes/moveo_link5.STL" />
      </geometry>
      <material
        name="">
        <color
          rgba="0.0980392156862745 0.0980392156862745 0.0980392156862745 1" />
      </material>
    </visual>
    <collision>
      <origin
        xyz="0 0 0"
        rpy="0 0 0" />
      <geometry>
        <mesh
          filename="package://moveo_urdf/meshes/moveo_link5.STL" />
      </geometry>
    </collision>
  </link>
  <joint
    name="moveo_joint5"
    type="revolute">
    <origin
      xyz="0 -0.00063427 0.094998"
      rpy="0 0 0" />
    <parent
      link="moveo_link4" />
    <child
      link="moveo_link5" />
    <axis
      xyz="-1 -0.00090423 0" />
    <limit
      lower="-1.4677"
      upper="1.9495"
      effort="10"
      velocity="100" />
  </joint>
  <link
    name="moveo_nozzle_link">
    <inertial>
      <origin
        xyz="0.0107619119851214 -0.0322441875696812 0.0697366925894372"
        rpy="0 0 0" />
      <mass
        value="0.55163957172068" />
      <inertia
        ixx="0.000150648841458262"
        ixy="-3.54118044765284E-07"
        ixz="7.42085812587951E-07"
        iyy="0.000170858555025238"
        iyz="7.33188644632045E-06"
        izz="0.000133653870648589" />
    </inertial>
    <visual>
      <origin
        xyz="0 0 0"
        rpy="0 0 0" />
      <geometry>
        <mesh
          filename="package://moveo_urdf/meshes/moveo_nozzle_link.STL" />
      </geometry>
      <material
        name="">
        <color
          rgba="0.427450980392157 0.447058823529412 0.427450980392157 1" />
      </material>
    </visual>
    <collision>
      <origin
        xyz="0 0 0"
        rpy="0 0 0" />
      <geometry>
        <mesh
          filename="package://moveo_urdf/meshes/moveo_nozzle_link.STL" />
      </geometry>
    </collision>
  </link>
  <joint
    name="moveo_nozzle_joint"
    type="fixed">
    <origin
      xyz="-0.010865 -0.039338 0.15111"
      rpy="-3.1368 0 0.00090423" />
    <parent
      link="moveo_link5" />
    <child
      link="moveo_nozzle_link" />
    <axis
      xyz="0 0 0" />
  </joint>
</robot>
