<?xml version="1.0" encoding="utf-8"?>
<!-- This URDF was automatically created by SolidWorks to URDF Exporter! Originally created by Stephen Brawner (brawner@gmail.com) 
     Commit Version: 1.5.1-0-g916b5db  Build Version: 1.5.7152.31018
     For more information, please see http://wiki.ros.org/sw_urdf_exporter -->
<robot
  name="moveo_urdf">
  <link
    name="dummy">
  </link>
  <link
    name="base_link">
    <inertial>
      <origin
        xyz="1.4509254414985E-05 1.4418080479528E-08 0.0371569473494335"
        rpy="0 0 0" />
      <mass
        value="0.637576232475362" />
      <inertia
        ixx="0.0015156408925581"
        ixy="-4.43771629903347E-10"
        ixz="-1.56908018120832E-07"
        iyy="0.00151491092167326"
        iyz="-1.90313578356678E-11"
        izz="0.00262377531863523" />
    </inertial>
    <visual>
      <origin
        xyz="0 0 0"
        rpy="0 0 0" />
      <geometry>
        <mesh
          filename="package://moveo_urdf/meshes/base_link.STL" />
      </geometry>
      <material
        name="">
        <color
          rgba="0.792156862745098 0.819607843137255 0.933333333333333 1" />
      </material>
    </visual>
    <collision>
      <origin
        xyz="0 0 0"
        rpy="0 0 0" />
      <geometry>
        <mesh
          filename="package://moveo_urdf/meshes/base_link.STL" />
      </geometry>
    </collision>
  </link>
  <link
    name="moveo_link1">
    <inertial>
      <origin
        xyz="0.000285408719369704 0.000113990477217468 0.0721937048044911"
        rpy="0 0 0" />
      <mass
        value="4.19319683049615" />
      <inertia
        ixx="0.00802674916420919"
        ixy="-3.76399390863906E-05"
        ixz="4.75789062133556E-07"
        iyy="0.0091031897649255"
        iyz="-7.68266595581936E-07"
        izz="0.00701289814427911" />
    </inertial>
    <visual>
      <origin
        xyz="0 0 0"
        rpy="0 0 0" />
      <geometry>
        <mesh
          filename="package://moveo_urdf/meshes/moveo_link1.STL" />
      </geometry>
      <material
        name="">
        <color
          rgba="0.0274509803921569 0.270588235294118 1 1" />
      </material>
    </visual>
    <collision>
      <origin
        xyz="0 0 0"
        rpy="0 0 0" />
      <geometry>
        <mesh
          filename="package://moveo_urdf/meshes/moveo_link1.STL" />
      </geometry>
    </collision>
  </link>
  <joint name="dummy_joint" type="fixed">
    <parent link="dummy"/>
    <child link="base_link"/>
  </joint>
  <joint
    name="moveo_joint1"
    type="revolute">
    <origin
      xyz="0 0 0.0665"
      rpy="0 0 0" />
    <parent
      link="base_link" />
    <child
      link="moveo_link1" />
    <axis
      xyz="0 0 1" />
    <limit
      lower="-2.15"
      upper="2.15"
      effort="10"
      velocity="100" />
  </joint>
  <link
    name="moveo_link2">
    <inertial>
      <origin
        xyz="-0.00125091560804545 -7.13701003474121E-06 0.0800784568273431"
        rpy="0 0 0" />
      <mass
        value="1.92822525077319" />
      <inertia
        ixx="0.00485700228691664"
        ixy="-5.27001356814751E-06"
        ixz="-9.67175201278879E-06"
        iyy="0.00497652060748986"
        iyz="-4.34591932469587E-07"
        izz="0.00289745654444462" />
    </inertial>
    <visual>
      <origin
        xyz="0 0 0"
        rpy="0 0 0" />
      <geometry>
        <mesh
          filename="package://moveo_urdf/meshes/moveo_link2.STL" />
      </geometry>
      <material
        name="">
        <color
          rgba="0.752941176470588 0.752941176470588 0.752941176470588 1" />
      </material>
    </visual>
    <collision>
      <origin
        xyz="0 0 0"
        rpy="0 0 0" />
      <geometry>
        <mesh
          filename="package://moveo_urdf/meshes/moveo_link2.STL" />
      </geometry>
    </collision>
  </link>
  <joint
    name="moveo_joint2"
    type="revolute">
    <origin
      xyz="0 0 0.165"
      rpy="0 0 0" />
    <parent
      link="moveo_link1" />
    <child
      link="moveo_link2" />
    <axis
      xyz="-0.99939 -0.035015 0" />
    <limit
      lower="-2.15"
      upper="2.15"
      effort="10"
      velocity="100" />
  </joint>
  <link
    name="moveo_link3">
    <inertial>
      <origin
        xyz="-0.000140027275863555 -0.000337083806844579 0.0389211157378916"
        rpy="0 0 0" />
      <mass
        value="0.645102540582945" />
      <inertia
        ixx="0.00197988817811377"
        ixy="1.00374588130944E-05"
        ixz="-6.55217772297345E-07"
        iyy="0.00169518445559943"
        iyz="7.92087507281797E-06"
        izz="0.000428096864888759" />
    </inertial>
    <visual>
      <origin
        xyz="0 0 0"
        rpy="0 0 0" />
      <geometry>
        <mesh
          filename="package://moveo_urdf/meshes/moveo_link3.STL" />
      </geometry>
      <material
        name="">
        <color
          rgba="1 1 1 1" />
      </material>
    </visual>
    <collision>
      <origin
        xyz="0 0 0"
        rpy="0 0 0" />
      <geometry>
        <mesh
          filename="package://moveo_urdf/meshes/moveo_link3.STL" />
      </geometry>
    </collision>
  </link>
  <joint
    name="moveo_joint3"
    type="revolute">
    <origin
      xyz="0.00099794 7.6228E-05 0.22112"
      rpy="0 0 0" />
    <parent
      link="moveo_link2" />
    <child
      link="moveo_link3" />
    <axis
      xyz="-0.99939 -0.035015 0" />
    <limit
      lower="-2.15"
      upper="2.15"
      effort="10"
      velocity="100" />
  </joint>
  <link
    name="moveo_link4">
    <inertial>
      <origin
        xyz="-0.00593451469965803 -0.000356863585480843 0.0505287064543694"
        rpy="0 0 0" />
      <mass
        value="0.361299996271292" />
      <inertia
        ixx="0.000521498022784987"
        ixy="-3.52262578773141E-06"
        ixz="4.88564852701096E-07"
        iyy="0.000625377542782631"
        iyz="1.18954738371832E-05"
        izz="0.000323114540996135" />
    </inertial>
    <visual>
      <origin
        xyz="0 0 0"
        rpy="0 0 0" />
      <geometry>
        <mesh
          filename="package://moveo_urdf/meshes/moveo_link4.STL" />
      </geometry>
      <material
        name="">
        <color
          rgba="0.294117647058824 0.294117647058824 0.294117647058824 1" />
      </material>
    </visual>
    <collision>
      <origin
        xyz="0 0 0"
        rpy="0 0 0" />
      <geometry>
        <mesh
          filename="package://moveo_urdf/meshes/moveo_link4.STL" />
      </geometry>
    </collision>
  </link>
  <joint
    name="moveo_joint4"
    type="revolute">
    <origin
      xyz="2.9924E-05 -0.00085408 0.128"
      rpy="0 0 0" />
    <parent
      link="moveo_link3" />
    <child
      link="moveo_link4" />
    <axis
      xyz="0.00023378 -0.0066725 0.99998" />
    <limit
      lower="-1.3745"
      upper="4.5161"
      effort="10"
      velocity="100" />
  </joint>
  <link
    name="moveo_link5">
    <inertial>
      <origin
        xyz="-0.000381752621358505 -1.92326528452857E-05 0.00379978894874755"
        rpy="0 0 0" />
      <mass
        value="0.157708113676862" />
      <inertia
        ixx="0.000105894876055904"
        ixy="1.3743572057056E-06"
        ixz="1.75421047343503E-07"
        iyy="6.7699139848321E-05"
        iyz="2.71070160073983E-08"
        izz="5.33063348258521E-05" />
    </inertial>
    <visual>
      <origin
        xyz="0 0 0"
        rpy="0 0 0" />
      <geometry>
        <mesh
          filename="package://moveo_urdf/meshes/moveo_link5.STL" />
      </geometry>
      <material
        name="">
        <color
          rgba="0.0980392156862745 0.0980392156862745 0.0980392156862745 1" />
      </material>
    </visual>
    <collision>
      <origin
        xyz="0 0 0"
        rpy="0 0 0" />
      <geometry>
        <mesh
          filename="package://moveo_urdf/meshes/moveo_link5.STL" />
      </geometry>
    </collision>
  </link>
  <joint
    name="moveo_joint5"
    type="revolute">
    <origin
      xyz="2.2209E-05 -0.00063389 0.094998"
      rpy="0 0 0" />
    <parent
      link="moveo_link4" />
    <child
      link="moveo_link5" />
    <axis
      xyz="-0.99935 -0.035911 -0.00011484" />
    <limit
      lower="-1.4677"
      upper="1.9495"
      effort="10"
      velocity="100" />
  </joint>
  <link
    name="moveo_nozzle_link">
    <inertial>
      <origin
        xyz="0.0107468514731608 -0.0322556491063275 0.0697463873719438"
        rpy="0 0 0" />
      <mass
        value="0.551332467270815" />
      <inertia
        ixx="0.00015059403433538"
        ixy="-3.54146485339003E-07"
        ixz="7.59624488723667E-07"
        iyy="0.000170796532495791"
        iyz="7.33186784525814E-06"
        izz="0.000133645321813503" />
    </inertial>
    <visual>
      <origin
        xyz="0 0 0"
        rpy="0 0 0" />
      <geometry>
        <mesh
          filename="package://moveo_urdf/meshes/moveo_nozzle_link.STL" />
      </geometry>
      <material
        name="">
        <color
          rgba="0.427450980392157 0.447058823529412 0.427450980392157 1" />
      </material>
    </visual>
    <collision>
      <origin
        xyz="0 0 0"
        rpy="0 0 0" />
      <geometry>
        <mesh
          filename="package://moveo_urdf/meshes/moveo_nozzle_link.STL" />
      </geometry>
    </collision>
  </link>
  <joint
    name="moveo_nozzle_joint"
    type="fixed">
    <origin
      xyz="-0.0094995 -0.039186 0.15124"
      rpy="-3.1401 0 0.035926" />
    <parent
      link="moveo_link5" />
    <child
      link="moveo_nozzle_link" />
    <axis
      xyz="0 0 0" />
  </joint>
</robot>
